Workbook

Sheet Assumptions
A1: DIRT MONEY — ECONOMY MODEL v1 (Phase 0)
A2: All blue cells are tunable inputs. Background sheets reference them. Source: docs/DIRT_MONEY_ECONOMY_SPEC.md, 2026-07-03.
A4: GLOBAL
A5: Starting cash ($) | B5: 1200
A6: Starting debt ($) | B6: 8000
A7: Debt daily interest | B7: 0.004
A8: Travel fuel per trip ($) | B8: 8
A9: Chickens (head) | B9: 12
A10: Eggs per chicken per day | B10: 0.8
A11: Egg price ($/egg) | B11: 0.4
A12: Feed per chicken per day ($) | B12: 0.08
A13: CROPS (per field cycle)
A14: Crop | B14: Plant cost $ | C14: Plant days | D14: Grow days | E14: Harvest cost $ | F14: Harvest days | G14: Yield (units) | H14: Price $/unit
A15: Corn | B15: 340 | C15: 2 | D15: 10 | E15: 180 | F15: 2 | G15: 300 | H15: 4.2
A16: Soybeans | B16: 220 | C16: 2 | D16: 9 | E16: 140 | F16: 1 | G16: 200 | H16: 10.5
A17: Hay (per cut) | B17: 90 | C17: 1 | D17: 6 | E17: 80 | F17: 1 | G17: 100 | H17: 5
A19: BACKGROUND MODIFIERS
A20: Old School: legacy premium (× spot) | B20: 1.35
A21: Old School: legacy contract units | B21: 450
A22: Old School: Hollis hauling favor ($) | B22: 120
A23: IT Nephew: labor cost multiplier | B23: 1.5
A24: IT Nephew: market-timing edge (× spot) | B24: 1.15
A25: IT Nephew: egg contract premium (× price) | B25: 1.2
A26: Mechanic: repair job pay ($) | B26: 250
A27: Mechanic: repair job parts cost ($) | B27: 60
A28: Mechanic: neighbor repair pay ($) | B28: 150
A29: Mechanic: flip - salvage buy ($) | B29: 400
A30: Mechanic: flip - restoration parts ($) | B30: 250
A31: Mechanic: flip - sale price ($) | B31: 1400
A33: Demo win condition: END CASH > 0 and net worth improved. Full loan payoff is multi-season (Phase 3) scope.

Sheet Old School
A1: OLD SCHOOL — 30-DAY CASH FLOW
A2: Corn on both big fields + hay; the storm-help unlock converts most of the corn to the legacy contract at a premium rate. Wins on relationships, not information.
A3: Income category gates: Negotiated = reputation-locked · Timed = info-locked · Repair & flip = wrench-locked
A5: Day | B5: Weekday | C5: Event | D5: Spot sales | E5: Negotiated (rep) | F5: Timed (info) | G5: Repair & flip | H5: Eggs & favors | I5: Costs | J5: Net | K5: Cash | L5: Debt | M5: Net worth
A6: 1 | B6: =CHOOSE(MOD(A6-1,7)+1,"Mon","Tue","Wed","Thu","Fri","Sat","Sun") | D6: 0 | E6: 0 | F6: 0 | G6: 0 | H6: =(Assumptions!$B$9*Assumptions!$B$10*Assumptions!$B$11)-(Assumptions!$B$9*Assumptions!$B$12) | I6: 0 | J6: =SUM(D6:H6)-I6 | K6: =Assumptions!$B$5+J6 | L6: =Assumptions!$B$6*(1+Assumptions!$B$7) | M6: =K6-L6
A7: 2 | B7: =CHOOSE(MOD(A7-1,7)+1,"Mon","Tue","Wed","Thu","Fri","Sat","Sun") | C7: Plant corn — North field | D7: 0 | E7: 0 | F7: 0 | G7: 0 | H7: =(Assumptions!$B$9*Assumptions!$B$10*Assumptions!$B$11)-(Assumptions!$B$9*Assumptions!$B$12) | I7: =Assumptions!$B$15+Assumptions!$B$8 | J7: =SUM(D7:H7)-I7 | K7: =K6+J7 | L7: =L6*(1+Assumptions!$B$7) | M7: =K7-L7
A8: 3 | B8: =CHOOSE(MOD(A8-1,7)+1,"Mon","Tue","Wed","Thu","Fri","Sat","Sun") | C8: Plant corn — South field | D8: 0 | E8: 0 | F8: 0 | G8: 0 | H8: =(Assumptions!$B$9*Assumptions!$B$10*Assumptions!$B$11)-(Assumptions!$B$9*Assumptions!$B$12) | I8: =Assumptions!$B$15+Assumptions!$B$8 | J8: =SUM(D8:H8)-I8 | K8: =K7+J8 | L8: =L7*(1+Assumptions!$B$7) | M8: =K8-L8
A9: 4 | B9: =CHOOSE(MOD(A9-1,7)+1,"Mon","Tue","Wed","Thu","Fri","Sat","Sun") | C9: Plant hay — East field | D9: 0 | E9: 0 | F9: 0 | G9: 0 | H9: =(Assumptions!$B$9*Assumptions!$B$10*Assumptions!$B$11)-(Assumptions!$B$9*Assumptions!$B$12) | I9: =Assumptions!$B$17+Assumptions!$B$8 | J9: =SUM(D9:H9)-I9 | K9: =K8+J9 | L9: =L8*(1+Assumptions!$B$7) | M9: =K9-L9
A10: 5 | B10: =CHOOSE(MOD(A10-1,7)+1,"Mon","Tue","Wed","Thu","Fri","Sat","Sun") | C10: Haul Hollis's hay (favor) | D10: 0 | E10: 0 | F10: 0 | G10: 0 | H10: =(Assumptions!$B$9*Assumptions!$B$10*Assumptions!$B$11)-(Assumptions!$B$9*Assumptions!$B$12)+Assumptions!$B$22 | I10: =Assumptions!$B$8 | J10: =SUM(D10:H10)-I10 | K10: =K9+J10 | L10: =L9*(1+Assumptions!$B$7) | M10: =K10-L10
A11: 6 | B11: =CHOOSE(MOD(A11-1,7)+1,"Mon","Tue","Wed","Thu","Fri","Sat","Sun") | D11: 0 | E11: 0 | F11: 0 | G11: 0 | H11: =(Assumptions!$B$9*Assumptions!$B$10*Assumptions!$B$11)-(Assumptions!$B$9*Assumptions!$B$12) | I11: 0 | J11: =SUM(D11:H11)-I11 | K11: =K10+J11 | L11: =L10*(1+Assumptions!$B$7) | M11: =K11-L11
A12: 7 | B12: =CHOOSE(MOD(A12-1,7)+1,"Mon","Tue","Wed","Thu","Fri","Sat","Sun") | D12: 0 | E12: 0 | F12: 0 | G12: 0 | H12: =(Assumptions!$B$9*Assumptions!$B$10*Assumptions!$B$11)-(Assumptions!$B$9*Assumptions!$B$12) | I12: 0 | J12: =SUM(D12:H12)-I12 | K12: =K11+J12 | L12: =L11*(1+Assumptions!$B$7) | M12: =K12-L12
A13: 8 | B13: =CHOOSE(MOD(A13-1,7)+1,"Mon","Tue","Wed","Thu","Fri","Sat","Sun") | C13: STORM — help Hollis sandbag (loses the day; unlocks legacy contract) | D13: 0 | E13: 0 | F13: 0 | G13: 0 | H13: =(Assumptions!$B$9*Assumptions!$B$10*Assumptions!$B$11)-(Assumptions!$B$9*Assumptions!$B$12) | I13: 0 | J13: =SUM(D13:H13)-I13 | K13: =K12+J13 | L13: =L12*(1+Assumptions!$B$7) | M13: =K13-L13
A14: 9 | B14: =CHOOSE(MOD(A14-1,7)+1,"Mon","Tue","Wed","Thu","Fri","Sat","Sun") | D14: 0 | E14: 0 | F14: 0 | G14: 0 | H14: =(Assumptions!$B$9*Assumptions!$B$10*Assumptions!$B$11)-(Assumptions!$B$9*Assumptions!$B$12) | I14: 0 | J14: =SUM(D14:H14)-I14 | K14: =K13+J14 | L14: =L13*(1+Assumptions!$B$7) | M14: =K14-L14
A15: 10 | B15: =CHOOSE(MOD(A15-1,7)+1,"Mon","Tue","Wed","Thu","Fri","Sat","Sun") | C15: Hay cut 1 — East | D15: =Assumptions!$G$17*Assumptions!$H$17 | E15: 0 | F15: 0 | G15: 0 | H15: =(Assumptions!$B$9*Assumptions!$B$10*Assumptions!$B$11)-(Assumptions!$B$9*Assumptions!$B$12) | I15: =Assumptions!$E$17 | J15: =SUM(D15:H15)-I15 | K15: =K14+J15 | L15: =L14*(1+Assumptions!$B$7) | M15: =K15-L15
A16: 11 | B16: =CHOOSE(MOD(A16-1,7)+1,"Mon","Tue","Wed","Thu","Fri","Sat","Sun") | D16: 0 | E16: 0 | F16: 0 | G16: 0 | H16: =(Assumptions!$B$9*Assumptions!$B$10*Assumptions!$B$11)-(Assumptions!$B$9*Assumptions!$B$12) | I16: 0 | J16: =SUM(D16:H16)-I16 | K16: =K15+J16 | L16: =L15*(1+Assumptions!$B$7) | M16: =K16-L16
A17: 12 | B17: =CHOOSE(MOD(A17-1,7)+1,"Mon","Tue","Wed","Thu","Fri","Sat","Sun") | D17: 0 | E17: 0 | F17: 0 | G17: 0 | H17: =(Assumptions!$B$9*Assumptions!$B$10*Assumptions!$B$11)-(Assumptions!$B$9*Assumptions!$B$12) | I17: 0 | J17: =SUM(D17:H17)-I17 | K17: =K16+J17 | L17: =L16*(1+Assumptions!$B$7) | M17: =K17-L17
A18: 13 | B18: =CHOOSE(MOD(A18-1,7)+1,"Mon","Tue","Wed","Thu","Fri","Sat","Sun") | D18: 0 | E18: 0 | F18: 0 | G18: 0 | H18: =(Assumptions!$B$9*Assumptions!$B$10*Assumptions!$B$11)-(Assumptions!$B$9*Assumptions!$B$12) | I18: 0 | J18: =SUM(D18:H18)-I18 | K18: =K17+J18 | L18: =L17*(1+Assumptions!$B$7) | M18: =K18-L18
A19: 14 | B19: =CHOOSE(MOD(A19-1,7)+1,"Mon","Tue","Wed","Thu","Fri","Sat","Sun") | C19: Harvest corn — North | D19: 0 | E19: 0 | F19: 0 | G19: 0 | H19: =(Assumptions!$B$9*Assumptions!$B$10*Assumptions!$B$11)-(Assumptions!$B$9*Assumptions!$B$12) | I19: =Assumptions!$E$15 | J19: =SUM(D19:H19)-I19 | K19: =K18+J19 | L19: =L18*(1+Assumptions!$B$7) | M19: =K19-L19
A20: 15 | B20: =CHOOSE(MOD(A20-1,7)+1,"Mon","Tue","Wed","Thu","Fri","Sat","Sun") | C20: Harvest corn — South | D20: 0 | E20: 0 | F20: 0 | G20: 0 | H20: =(Assumptions!$B$9*Assumptions!$B$10*Assumptions!$B$11)-(Assumptions!$B$9*Assumptions!$B$12) | I20: =Assumptions!$E$15 | J20: =SUM(D20:H20)-I20 | K20: =K19+J20 | L20: =L19*(1+Assumptions!$B$7) | M20: =K20-L20
A21: 16 | B21: =CHOOSE(MOD(A21-1,7)+1,"Mon","Tue","Wed","Thu","Fri","Sat","Sun") | C21: Deliver legacy contract corn (the Vann family rate) | D21: 0 | E21: =Assumptions!$B$21*Assumptions!$H$15*Assumptions!$B$20 | F21: 0 | G21: 0 | H21: =(Assumptions!$B$9*Assumptions!$B$10*Assumptions!$B$11)-(Assumptions!$B$9*Assumptions!$B$12) | I21: =Assumptions!$B$8 | J21: =SUM(D21:H21)-I21 | K21: =K20+J21 | L21: =L20*(1+Assumptions!$B$7) | M21: =K21-L21
A22: 17 | B22: =CHOOSE(MOD(A22-1,7)+1,"Mon","Tue","Wed","Thu","Fri","Sat","Sun") | C22: Sell remaining corn at spot; Hay cut 2 — East | D22: =(2*Assumptions!$G$15-Assumptions!$B$21)*Assumptions!$H$15+Assumptions!$G$17*Assumptions!$H$17 | E22: 0 | F22: 0 | G22: 0 | H22: =(Assumptions!$B$9*Assumptions!$B$10*Assumptions!$B$11)-(Assumptions!$B$9*Assumptions!$B$12) | I22: =Assumptions!$B$8+Assumptions!$E$17 | J22: =SUM(D22:H22)-I22 | K22: =K21+J22 | L22: =L21*(1+Assumptions!$B$7) | M22: =K22-L22
A23: 18 | B23: =CHOOSE(MOD(A23-1,7)+1,"Mon","Tue","Wed","Thu","Fri","Sat","Sun") | D23: 0 | E23: 0 | F23: 0 | G23: 0 | H23: =(Assumptions!$B$9*Assumptions!$B$10*Assumptions!$B$11)-(Assumptions!$B$9*Assumptions!$B$12) | I23: 0 | J23: =SUM(D23:H23)-I23 | K23: =K22+J23 | L23: =L22*(1+Assumptions!$B$7) | M23: =K23-L23
A24: 19 | B24: =CHOOSE(MOD(A24-1,7)+1,"Mon","Tue","Wed","Thu","Fri","Sat","Sun") | D24: 0 | E24: 0 | F24: 0 | G24: 0 | H24: =(Assumptions!$B$9*Assumptions!$B$10*Assumptions!$B$11)-(Assumptions!$B$9*Assumptions!$B$12) | I24: 0 | J24: =SUM(D24:H24)-I24 | K24: =K23+J24 | L24: =L23*(1+Assumptions!$B$7) | M24: =K24-L24
A25: 20 | B25: =CHOOSE(MOD(A25-1,7)+1,"Mon","Tue","Wed","Thu","Fri","Sat","Sun") | D25: 0 | E25: 0 | F25: 0 | G25: 0 | H25: =(Assumptions!$B$9*Assumptions!$B$10*Assumptions!$B$11)-(Assumptions!$B$9*Assumptions!$B$12) | I25: 0 | J25: =SUM(D25:H25)-I25 | K25: =K24+J25 | L25: =L24*(1+Assumptions!$B$7) | M25: =K25-L25
A26: 21 | B26: =CHOOSE(MOD(A26-1,7)+1,"Mon","Tue","Wed","Thu","Fri","Sat","Sun") | D26: 0 | E26: 0 | F26: 0 | G26: 0 | H26: =(Assumptions!$B$9*Assumptions!$B$10*Assumptions!$B$11)-(Assumptions!$B$9*Assumptions!$B$12) | I26: 0 | J26: =SUM(D26:H26)-I26 | K26: =K25+J26 | L26: =L25*(1+Assumptions!$B$7) | M26: =K26-L26
A27: 22 | B27: =CHOOSE(MOD(A27-1,7)+1,"Mon","Tue","Wed","Thu","Fri","Sat","Sun") | D27: 0 | E27: 0 | F27: 0 | G27: 0 | H27: =(Assumptions!$B$9*Assumptions!$B$10*Assumptions!$B$11)-(Assumptions!$B$9*Assumptions!$B$12) | I27: 0 | J27: =SUM(D27:H27)-I27 | K27: =K26+J27 | L27: =L26*(1+Assumptions!$B$7) | M27: =K27-L27
A28: 23 | B28: =CHOOSE(MOD(A28-1,7)+1,"Mon","Tue","Wed","Thu","Fri","Sat","Sun") | D28: 0 | E28: 0 | F28: 0 | G28: 0 | H28: =(Assumptions!$B$9*Assumptions!$B$10*Assumptions!$B$11)-(Assumptions!$B$9*Assumptions!$B$12) | I28: 0 | J28: =SUM(D28:H28)-I28 | K28: =K27+J28 | L28: =L27*(1+Assumptions!$B$7) | M28: =K28-L28
A29: 24 | B29: =CHOOSE(MOD(A29-1,7)+1,"Mon","Tue","Wed","Thu","Fri","Sat","Sun") | C29: Hay cut 3 — East | D29: =Assumptions!$G$17*Assumptions!$H$17 | E29: 0 | F29: 0 | G29: 0 | H29: =(Assumptions!$B$9*Assumptions!$B$10*Assumptions!$B$11)-(Assumptions!$B$9*Assumptions!$B$12) | I29: =Assumptions!$E$17 | J29: =SUM(D29:H29)-I29 | K29: =K28+J29 | L29: =L28*(1+Assumptions!$B$7) | M29: =K29-L29
A30: 25 | B30: =CHOOSE(MOD(A30-1,7)+1,"Mon","Tue","Wed","Thu","Fri","Sat","Sun") | D30: 0 | E30: 0 | F30: 0 | G30: 0 | H30: =(Assumptions!$B$9*Assumptions!$B$10*Assumptions!$B$11)-(Assumptions!$B$9*Assumptions!$B$12) | I30: 0 | J30: =SUM(D30:H30)-I30 | K30: =K29+J30 | L30: =L29*(1+Assumptions!$B$7) | M30: =K30-L30
A31: 26 | B31: =CHOOSE(MOD(A31-1,7)+1,"Mon","Tue","Wed","Thu","Fri","Sat","Sun") | D31: 0 | E31: 0 | F31: 0 | G31: 0 | H31: =(Assumptions!$B$9*Assumptions!$B$10*Assumptions!$B$11)-(Assumptions!$B$9*Assumptions!$B$12) | I31: 0 | J31: =SUM(D31:H31)-I31 | K31: =K30+J31 | L31: =L30*(1+Assumptions!$B$7) | M31: =K31-L31
A32: 27 | B32: =CHOOSE(MOD(A32-1,7)+1,"Mon","Tue","Wed","Thu","Fri","Sat","Sun") | D32: 0 | E32: 0 | F32: 0 | G32: 0 | H32: =(Assumptions!$B$9*Assumptions!$B$10*Assumptions!$B$11)-(Assumptions!$B$9*Assumptions!$B$12) | I32: 0 | J32: =SUM(D32:H32)-I32 | K32: =K31+J32 | L32: =L31*(1+Assumptions!$B$7) | M32: =K32-L32
A33: 28 | B33: =CHOOSE(MOD(A33-1,7)+1,"Mon","Tue","Wed","Thu","Fri","Sat","Sun") | D33: 0 | E33: 0 | F33: 0 | G33: 0 | H33: =(Assumptions!$B$9*Assumptions!$B$10*Assumptions!$B$11)-(Assumptions!$B$9*Assumptions!$B$12) | I33: 0 | J33: =SUM(D33:H33)-I33 | K33: =K32+J33 | L33: =L32*(1+Assumptions!$B$7) | M33: =K33-L33
A34: 29 | B34: =CHOOSE(MOD(A34-1,7)+1,"Mon","Tue","Wed","Thu","Fri","Sat","Sun") | D34: 0 | E34: 0 | F34: 0 | G34: 0 | H34: =(Assumptions!$B$9*Assumptions!$B$10*Assumptions!$B$11)-(Assumptions!$B$9*Assumptions!$B$12) | I34: 0 | J34: =SUM(D34:H34)-I34 | K34: =K33+J34 | L34: =L33*(1+Assumptions!$B$7) | M34: =K34-L34
A35: 30 | B35: =CHOOSE(MOD(A35-1,7)+1,"Mon","Tue","Wed","Thu","Fri","Sat","Sun") | D35: 0 | E35: 0 | F35: 0 | G35: 0 | H35: =(Assumptions!$B$9*Assumptions!$B$10*Assumptions!$B$11)-(Assumptions!$B$9*Assumptions!$B$12) | I35: 0 | J35: =SUM(D35:H35)-I35 | K35: =K34+J35 | L35: =L34*(1+Assumptions!$B$7) | M35: =K35-L35
A37: RUN SUMMARY
A38: Total spot sales | B38: =SUM(D6:D35)
A39: Total negotiated (rep) | B39: =SUM(E6:E35)
A40: Total timed (info) | B40: =SUM(F6:F35)
A41: Total repair & flip | B41: =SUM(G6:G35)
A42: Total eggs & favors | B42: =SUM(H6:H35)
...

Sheet IT Nephew
A1: IT NEPHEW — 30-DAY CASH FLOW
A2: Higher labor costs force crop selection by the numbers: soybeans + corn, all sales timed off the forecast for the arbitrage edge. Egg contract renegotiated on day 1 with data. Wins on information, not relationships.
A3: Income category gates: Negotiated = reputation-locked · Timed = info-locked · Repair & flip = wrench-locked
A5: Day | B5: Weekday | C5: Event | D5: Spot sales | E5: Negotiated (rep) | F5: Timed (info) | G5: Repair & flip | H5: Eggs & favors | I5: Costs | J5: Net | K5: Cash | L5: Debt | M5: Net worth
A6: 1 | B6: =CHOOSE(MOD(A6-1,7)+1,"Mon","Tue","Wed","Thu","Fri","Sat","Sun") | C6: Audit Marge's egg contract — premium locked in (data check) | D6: 0 | E6: 0 | F6: 0 | G6: 0 | H6: =(Assumptions!$B$9*Assumptions!$B$10*Assumptions!$B$11*Assumptions!$B$25)-(Assumptions!$B$9*Assumptions!$B$12*IF(A6>=20,0,1)) | I6: 0 | J6: =SUM(D6:H6)-I6 | K6: =Assumptions!$B$5+J6 | L6: =Assumptions!$B$6*(1+Assumptions!$B$7) | M6: =K6-L6
A7: 2 | B7: =CHOOSE(MOD(A7-1,7)+1,"Mon","Tue","Wed","Thu","Fri","Sat","Sun") | C7: Plant corn — North (hired labor) | D7: 0 | E7: 0 | F7: 0 | G7: 0 | H7: =(Assumptions!$B$9*Assumptions!$B$10*Assumptions!$B$11*Assumptions!$B$25)-(Assumptions!$B$9*Assumptions!$B$12*IF(A7>=20,0,1)) | I7: =Assumptions!$B$15*Assumptions!$B$23+Assumptions!$B$8 | J7: =SUM(D7:H7)-I7 | K7: =K6+J7 | L7: =L6*(1+Assumptions!$B$7) | M7: =K7-L7
A8: 3 | B8: =CHOOSE(MOD(A8-1,7)+1,"Mon","Tue","Wed","Thu","Fri","Sat","Sun") | C8: Plant soybeans — South (hired labor) | D8: 0 | E8: 0 | F8: 0 | G8: 0 | H8: =(Assumptions!$B$9*Assumptions!$B$10*Assumptions!$B$11*Assumptions!$B$25)-(Assumptions!$B$9*Assumptions!$B$12*IF(A8>=20,0,1)) | I8: =Assumptions!$B$16*Assumptions!$B$23+Assumptions!$B$8 | J8: =SUM(D8:H8)-I8 | K8: =K7+J8 | L8: =L7*(1+Assumptions!$B$7) | M8: =K8-L8
A9: 4 | B9: =CHOOSE(MOD(A9-1,7)+1,"Mon","Tue","Wed","Thu","Fri","Sat","Sun") | D9: 0 | E9: 0 | F9: 0 | G9: 0 | H9: =(Assumptions!$B$9*Assumptions!$B$10*Assumptions!$B$11*Assumptions!$B$25)-(Assumptions!$B$9*Assumptions!$B$12*IF(A9>=20,0,1)) | I9: 0 | J9: =SUM(D9:H9)-I9 | K9: =K8+J9 | L9: =L8*(1+Assumptions!$B$7) | M9: =K9-L9
A10: 5 | B10: =CHOOSE(MOD(A10-1,7)+1,"Mon","Tue","Wed","Thu","Fri","Sat","Sun") | D10: 0 | E10: 0 | F10: 0 | G10: 0 | H10: =(Assumptions!$B$9*Assumptions!$B$10*Assumptions!$B$11*Assumptions!$B$25)-(Assumptions!$B$9*Assumptions!$B$12*IF(A10>=20,0,1)) | I10: 0 | J10: =SUM(D10:H10)-I10 | K10: =K9+J10 | L10: =L9*(1+Assumptions!$B$7) | M10: =K10-L10
A11: 6 | B11: =CHOOSE(MOD(A11-1,7)+1,"Mon","Tue","Wed","Thu","Fri","Sat","Sun") | D11: 0 | E11: 0 | F11: 0 | G11: 0 | H11: =(Assumptions!$B$9*Assumptions!$B$10*Assumptions!$B$11*Assumptions!$B$25)-(Assumptions!$B$9*Assumptions!$B$12*IF(A11>=20,0,1)) | I11: 0 | J11: =SUM(D11:H11)-I11 | K11: =K10+J11 | L11: =L10*(1+Assumptions!$B$7) | M11: =K11-L11
A12: 7 | B12: =CHOOSE(MOD(A12-1,7)+1,"Mon","Tue","Wed","Thu","Fri","Sat","Sun") | D12: 0 | E12: 0 | F12: 0 | G12: 0 | H12: =(Assumptions!$B$9*Assumptions!$B$10*Assumptions!$B$11*Assumptions!$B$25)-(Assumptions!$B$9*Assumptions!$B$12*IF(A12>=20,0,1)) | I12: 0 | J12: =SUM(D12:H12)-I12 | K12: =K11+J12 | L12: =L11*(1+Assumptions!$B$7) | M12: =K12-L12
A13: 8 | B13: =CHOOSE(MOD(A13-1,7)+1,"Mon","Tue","Wed","Thu","Fri","Sat","Sun") | D13: 0 | E13: 0 | F13: 0 | G13: 0 | H13: =(Assumptions!$B$9*Assumptions!$B$10*Assumptions!$B$11*Assumptions!$B$25)-(Assumptions!$B$9*Assumptions!$B$12*IF(A13>=20,0,1)) | I13: 0 | J13: =SUM(D13:H13)-I13 | K13: =K12+J13 | L13: =L12*(1+Assumptions!$B$7) | M13: =K13-L13
A14: 9 | B14: =CHOOSE(MOD(A14-1,7)+1,"Mon","Tue","Wed","Thu","Fri","Sat","Sun") | D14: 0 | E14: 0 | F14: 0 | G14: 0 | H14: =(Assumptions!$B$9*Assumptions!$B$10*Assumptions!$B$11*Assumptions!$B$25)-(Assumptions!$B$9*Assumptions!$B$12*IF(A14>=20,0,1)) | I14: 0 | J14: =SUM(D14:H14)-I14 | K14: =K13+J14 | L14: =L13*(1+Assumptions!$B$7) | M14: =K14-L14
A15: 10 | B15: =CHOOSE(MOD(A15-1,7)+1,"Mon","Tue","Wed","Thu","Fri","Sat","Sun") | D15: 0 | E15: 0 | F15: 0 | G15: 0 | H15: =(Assumptions!$B$9*Assumptions!$B$10*Assumptions!$B$11*Assumptions!$B$25)-(Assumptions!$B$9*Assumptions!$B$12*IF(A15>=20,0,1)) | I15: 0 | J15: =SUM(D15:H15)-I15 | K15: =K14+J15 | L15: =L14*(1+Assumptions!$B$7) | M15: =K15-L15
A16: 11 | B16: =CHOOSE(MOD(A16-1,7)+1,"Mon","Tue","Wed","Thu","Fri","Sat","Sun") | D16: 0 | E16: 0 | F16: 0 | G16: 0 | H16: =(Assumptions!$B$9*Assumptions!$B$10*Assumptions!$B$11*Assumptions!$B$25)-(Assumptions!$B$9*Assumptions!$B$12*IF(A16>=20,0,1)) | I16: 0 | J16: =SUM(D16:H16)-I16 | K16: =K15+J16 | L16: =L15*(1+Assumptions!$B$7) | M16: =K16-L16
A17: 12 | B17: =CHOOSE(MOD(A17-1,7)+1,"Mon","Tue","Wed","Thu","Fri","Sat","Sun") | C17: Harvest soybeans — South | D17: 0 | E17: 0 | F17: 0 | G17: 0 | H17: =(Assumptions!$B$9*Assumptions!$B$10*Assumptions!$B$11*Assumptions!$B$25)-(Assumptions!$B$9*Assumptions!$B$12*IF(A17>=20,0,1)) | I17: =Assumptions!$E$16*Assumptions!$B$23 | J17: =SUM(D17:H17)-I17 | K17: =K16+J17 | L17: =L16*(1+Assumptions!$B$7) | M17: =K17-L17
A18: 13 | B18: =CHOOSE(MOD(A18-1,7)+1,"Mon","Tue","Wed","Thu","Fri","Sat","Sun") | D18: 0 | E18: 0 | F18: 0 | G18: 0 | H18: =(Assumptions!$B$9*Assumptions!$B$10*Assumptions!$B$11*Assumptions!$B$25)-(Assumptions!$B$9*Assumptions!$B$12*IF(A18>=20,0,1)) | I18: 0 | J18: =SUM(D18:H18)-I18 | K18: =K17+J18 | L18: =L17*(1+Assumptions!$B$7) | M18: =K18-L18
A19: 14 | B19: =CHOOSE(MOD(A19-1,7)+1,"Mon","Tue","Wed","Thu","Fri","Sat","Sun") | C19: Harvest corn — North | D19: 0 | E19: 0 | F19: 0 | G19: 0 | H19: =(Assumptions!$B$9*Assumptions!$B$10*Assumptions!$B$11*Assumptions!$B$25)-(Assumptions!$B$9*Assumptions!$B$12*IF(A19>=20,0,1)) | I19: =Assumptions!$E$15*Assumptions!$B$23 | J19: =SUM(D19:H19)-I19 | K19: =K18+J19 | L19: =L18*(1+Assumptions!$B$7) | M19: =K19-L19
A20: 15 | B20: =CHOOSE(MOD(A20-1,7)+1,"Mon","Tue","Wed","Thu","Fri","Sat","Sun") | C20: Sell soybeans on forecast spike | D20: 0 | E20: 0 | F20: =Assumptions!$G$16*Assumptions!$H$16*Assumptions!$B$24 | G20: 0 | H20: =(Assumptions!$B$9*Assumptions!$B$10*Assumptions!$B$11*Assumptions!$B$25)-(Assumptions!$B$9*Assumptions!$B$12*IF(A20>=20,0,1)) | I20: =Assumptions!$B$8 | J20: =SUM(D20:H20)-I20 | K20: =K19+J20 | L20: =L19*(1+Assumptions!$B$7) | M20: =K20-L20
A21: 16 | B21: =CHOOSE(MOD(A21-1,7)+1,"Mon","Tue","Wed","Thu","Fri","Sat","Sun") | D21: 0 | E21: 0 | F21: 0 | G21: 0 | H21: =(Assumptions!$B$9*Assumptions!$B$10*Assumptions!$B$11*Assumptions!$B$25)-(Assumptions!$B$9*Assumptions!$B$12*IF(A21>=20,0,1)) | I21: 0 | J21: =SUM(D21:H21)-I21 | K21: =K20+J21 | L21: =L20*(1+Assumptions!$B$7) | M21: =K21-L21
A22: 17 | B22: =CHOOSE(MOD(A22-1,7)+1,"Mon","Tue","Wed","Thu","Fri","Sat","Sun") | C22: Sell corn on forecast spike | D22: 0 | E22: 0 | F22: =Assumptions!$G$15*Assumptions!$H$15*Assumptions!$B$24 | G22: 0 | H22: =(Assumptions!$B$9*Assumptions!$B$10*Assumptions!$B$11*Assumptions!$B$25)-(Assumptions!$B$9*Assumptions!$B$12*IF(A22>=20,0,1)) | I22: =Assumptions!$B$8 | J22: =SUM(D22:H22)-I22 | K22: =K21+J22 | L22: =L21*(1+Assumptions!$B$7) | M22: =K22-L22
A23: 18 | B23: =CHOOSE(MOD(A23-1,7)+1,"Mon","Tue","Wed","Thu","Fri","Sat","Sun") | D23: 0 | E23: 0 | F23: 0 | G23: 0 | H23: =(Assumptions!$B$9*Assumptions!$B$10*Assumptions!$B$11*Assumptions!$B$25)-(Assumptions!$B$9*Assumptions!$B$12*IF(A23>=20,0,1)) | I23: 0 | J23: =SUM(D23:H23)-I23 | K23: =K22+J23 | L23: =L22*(1+Assumptions!$B$7) | M23: =K23-L23
A24: 19 | B24: =CHOOSE(MOD(A24-1,7)+1,"Mon","Tue","Wed","Thu","Fri","Sat","Sun") | D24: 0 | E24: 0 | F24: 0 | G24: 0 | H24: =(Assumptions!$B$9*Assumptions!$B$10*Assumptions!$B$11*Assumptions!$B$25)-(Assumptions!$B$9*Assumptions!$B$12*IF(A24>=20,0,1)) | I24: 0 | J24: =SUM(D24:H24)-I24 | K24: =K23+J24 | L24: =L23*(1+Assumptions!$B$7) | M24: =K24-L24
A25: 20 | B25: =CHOOSE(MOD(A25-1,7)+1,"Mon","Tue","Wed","Thu","Fri","Sat","Sun") | C25: Coop automation online — feed cost eliminated (perk) | D25: 0 | E25: 0 | F25: 0 | G25: 0 | H25: =(Assumptions!$B$9*Assumptions!$B$10*Assumptions!$B$11*Assumptions!$B$25)-(Assumptions!$B$9*Assumptions!$B$12*IF(A25>=20,0,1)) | I25: 0 | J25: =SUM(D25:H25)-I25 | K25: =K24+J25 | L25: =L24*(1+Assumptions!$B$7) | M25: =K25-L25
A26: 21 | B26: =CHOOSE(MOD(A26-1,7)+1,"Mon","Tue","Wed","Thu","Fri","Sat","Sun") | D26: 0 | E26: 0 | F26: 0 | G26: 0 | H26: =(Assumptions!$B$9*Assumptions!$B$10*Assumptions!$B$11*Assumptions!$B$25)-(Assumptions!$B$9*Assumptions!$B$12*IF(A26>=20,0,1)) | I26: 0 | J26: =SUM(D26:H26)-I26 | K26: =K25+J26 | L26: =L25*(1+Assumptions!$B$7) | M26: =K26-L26
A27: 22 | B27: =CHOOSE(MOD(A27-1,7)+1,"Mon","Tue","Wed","Thu","Fri","Sat","Sun") | D27: 0 | E27: 0 | F27: 0 | G27: 0 | H27: =(Assumptions!$B$9*Assumptions!$B$10*Assumptions!$B$11*Assumptions!$B$25)-(Assumptions!$B$9*Assumptions!$B$12*IF(A27>=20,0,1)) | I27: 0 | J27: =SUM(D27:H27)-I27 | K27: =K26+J27 | L27: =L26*(1+Assumptions!$B$7) | M27: =K27-L27
A28: 23 | B28: =CHOOSE(MOD(A28-1,7)+1,"Mon","Tue","Wed","Thu","Fri","Sat","Sun") | D28: 0 | E28: 0 | F28: 0 | G28: 0 | H28: =(Assumptions!$B$9*Assumptions!$B$10*Assumptions!$B$11*Assumptions!$B$25)-(Assumptions!$B$9*Assumptions!$B$12*IF(A28>=20,0,1)) | I28: 0 | J28: =SUM(D28:H28)-I28 | K28: =K27+J28 | L28: =L27*(1+Assumptions!$B$7) | M28: =K28-L28
A29: 24 | B29: =CHOOSE(MOD(A29-1,7)+1,"Mon","Tue","Wed","Thu","Fri","Sat","Sun") | D29: 0 | E29: 0 | F29: 0 | G29: 0 | H29: =(Assumptions!$B$9*Assumptions!$B$10*Assumptions!$B$11*Assumptions!$B$25)-(Assumptions!$B$9*Assumptions!$B$12*IF(A29>=20,0,1)) | I29: 0 | J29: =SUM(D29:H29)-I29 | K29: =K28+J29 | L29: =L28*(1+Assumptions!$B$7) | M29: =K29-L29
A30: 25 | B30: =CHOOSE(MOD(A30-1,7)+1,"Mon","Tue","Wed","Thu","Fri","Sat","Sun") | D30: 0 | E30: 0 | F30: 0 | G30: 0 | H30: =(Assumptions!$B$9*Assumptions!$B$10*Assumptions!$B$11*Assumptions!$B$25)-(Assumptions!$B$9*Assumptions!$B$12*IF(A30>=20,0,1)) | I30: 0 | J30: =SUM(D30:H30)-I30 | K30: =K29+J30 | L30: =L29*(1+Assumptions!$B$7) | M30: =K30-L30
A31: 26 | B31: =CHOOSE(MOD(A31-1,7)+1,"Mon","Tue","Wed","Thu","Fri","Sat","Sun") | D31: 0 | E31: 0 | F31: 0 | G31: 0 | H31: =(Assumptions!$B$9*Assumptions!$B$10*Assumptions!$B$11*Assumptions!$B$25)-(Assumptions!$B$9*Assumptions!$B$12*IF(A31>=20,0,1)) | I31: 0 | J31: =SUM(D31:H31)-I31 | K31: =K30+J31 | L31: =L30*(1+Assumptions!$B$7) | M31: =K31-L31
A32: 27 | B32: =CHOOSE(MOD(A32-1,7)+1,"Mon","Tue","Wed","Thu","Fri","Sat","Sun") | D32: 0 | E32: 0 | F32: 0 | G32: 0 | H32: =(Assumptions!$B$9*Assumptions!$B$10*Assumptions!$B$11*Assumptions!$B$25)-(Assumptions!$B$9*Assumptions!$B$12*IF(A32>=20,0,1)) | I32: 0 | J32: =SUM(D32:H32)-I32 | K32: =K31+J32 | L32: =L31*(1+Assumptions!$B$7) | M32: =K32-L32
A33: 28 | B33: =CHOOSE(MOD(A33-1,7)+1,"Mon","Tue","Wed","Thu","Fri","Sat","Sun") | D33: 0 | E33: 0 | F33: 0 | G33: 0 | H33: =(Assumptions!$B$9*Assumptions!$B$10*Assumptions!$B$11*Assumptions!$B$25)-(Assumptions!$B$9*Assumptions!$B$12*IF(A33>=20,0,1)) | I33: 0 | J33: =SUM(D33:H33)-I33 | K33: =K32+J33 | L33: =L32*(1+Assumptions!$B$7) | M33: =K33-L33
A34: 29 | B34: =CHOOSE(MOD(A34-1,7)+1,"Mon","Tue","Wed","Thu","Fri","Sat","Sun") | D34: 0 | E34: 0 | F34: 0 | G34: 0 | H34: =(Assumptions!$B$9*Assumptions!$B$10*Assumptions!$B$11*Assumptions!$B$25)-(Assumptions!$B$9*Assumptions!$B$12*IF(A34>=20,0,1)) | I34: 0 | J34: =SUM(D34:H34)-I34 | K34: =K33+J34 | L34: =L33*(1+Assumptions!$B$7) | M34: =K34-L34
A35: 30 | B35: =CHOOSE(MOD(A35-1,7)+1,"Mon","Tue","Wed","Thu","Fri","Sat","Sun") | D35: 0 | E35: 0 | F35: 0 | G35: 0 | H35: =(Assumptions!$B$9*Assumptions!$B$10*Assumptions!$B$11*Assumptions!$B$25)-(Assumptions!$B$9*Assumptions!$B$12*IF(A35>=20,0,1)) | I35: 0 | J35: =SUM(D35:H35)-I35 | K35: =K34+J35 | L35: =L34*(1+Assumptions!$B$7) | M35: =K35-L35
A37: RUN SUMMARY
A38: Total spot sales | B38: =SUM(D6:D35)
A39: Total negotiated (rep) | B39: =SUM(E6:E35)
A40: Total timed (info) | B40: =SUM(F6:F35)
A41: Total repair & flip | B41: =SUM(G6:G35)
A42: Total eggs & favors | B42: =SUM(H6:H35)
...

Sheet Mechanic
A1: MECHANIC — 30-DAY CASH FLOW
A2: Farms lightly (hay only); income is repair contracts and a salvage restoration flip. The baler fix on day 4 opens the co-op repair pipeline. Wins on skill, not acreage.
A3: Income category gates: Negotiated = reputation-locked · Timed = info-locked · Repair & flip = wrench-locked
A5: Day | B5: Weekday | C5: Event | D5: Spot sales | E5: Negotiated (rep) | F5: Timed (info) | G5: Repair & flip | H5: Eggs & favors | I5: Costs | J5: Net | K5: Cash | L5: Debt | M5: Net worth
A6: 1 | B6: =CHOOSE(MOD(A6-1,7)+1,"Mon","Tue","Wed","Thu","Fri","Sat","Sun") | D6: 0 | E6: 0 | F6: 0 | G6: 0 | H6: =(Assumptions!$B$9*Assumptions!$B$10*Assumptions!$B$11)-(Assumptions!$B$9*Assumptions!$B$12) | I6: 0 | J6: =SUM(D6:H6)-I6 | K6: =Assumptions!$B$5+J6 | L6: =Assumptions!$B$6*(1+Assumptions!$B$7) | M6: =K6-L6
A7: 2 | B7: =CHOOSE(MOD(A7-1,7)+1,"Mon","Tue","Wed","Thu","Fri","Sat","Sun") | C7: Plant hay — East field | D7: 0 | E7: 0 | F7: 0 | G7: 0 | H7: =(Assumptions!$B$9*Assumptions!$B$10*Assumptions!$B$11)-(Assumptions!$B$9*Assumptions!$B$12) | I7: =Assumptions!$B$17+Assumptions!$B$8 | J7: =SUM(D7:H7)-I7 | K7: =K6+J7 | L7: =L6*(1+Assumptions!$B$7) | M7: =K7-L7
A8: 3 | B8: =CHOOSE(MOD(A8-1,7)+1,"Mon","Tue","Wed","Thu","Fri","Sat","Sun") | D8: 0 | E8: 0 | F8: 0 | G8: 0 | H8: =(Assumptions!$B$9*Assumptions!$B$10*Assumptions!$B$11)-(Assumptions!$B$9*Assumptions!$B$12) | I8: 0 | J8: =SUM(D8:H8)-I8 | K8: =K7+J8 | L8: =L7*(1+Assumptions!$B$7) | M8: =K8-L8
A9: 4 | B9: =CHOOSE(MOD(A9-1,7)+1,"Mon","Tue","Wed","Thu","Fri","Sat","Sun") | C9: Fix Hollis's baler (check) — co-op repair contract unlocks | D9: 0 | E9: 0 | F9: 0 | G9: 0 | H9: =(Assumptions!$B$9*Assumptions!$B$10*Assumptions!$B$11)-(Assumptions!$B$9*Assumptions!$B$12) | I9: 0 | J9: =SUM(D9:H9)-I9 | K9: =K8+J9 | L9: =L8*(1+Assumptions!$B$7) | M9: =K9-L9
A10: 5 | B10: =CHOOSE(MOD(A10-1,7)+1,"Mon","Tue","Wed","Thu","Fri","Sat","Sun") | D10: 0 | E10: 0 | F10: 0 | G10: 0 | H10: =(Assumptions!$B$9*Assumptions!$B$10*Assumptions!$B$11)-(Assumptions!$B$9*Assumptions!$B$12) | I10: 0 | J10: =SUM(D10:H10)-I10 | K10: =K9+J10 | L10: =L9*(1+Assumptions!$B$7) | M10: =K10-L10
A11: 6 | B11: =CHOOSE(MOD(A11-1,7)+1,"Mon","Tue","Wed","Thu","Fri","Sat","Sun") | C11: Neighbor repair job | D11: 0 | E11: 0 | F11: 0 | G11: =Assumptions!$B$28 | H11: =(Assumptions!$B$9*Assumptions!$B$10*Assumptions!$B$11)-(Assumptions!$B$9*Assumptions!$B$12) | I11: =Assumptions!$B$8 | J11: =SUM(D11:H11)-I11 | K11: =K10+J11 | L11: =L10*(1+Assumptions!$B$7) | M11: =K11-L11
A12: 7 | B12: =CHOOSE(MOD(A12-1,7)+1,"Mon","Tue","Wed","Thu","Fri","Sat","Sun") | C12: Co-op repair job 1/3 | D12: 0 | E12: 0 | F12: 0 | G12: =Assumptions!$B$26 | H12: =(Assumptions!$B$9*Assumptions!$B$10*Assumptions!$B$11)-(Assumptions!$B$9*Assumptions!$B$12) | I12: =Assumptions!$B$27+Assumptions!$B$8 | J12: =SUM(D12:H12)-I12 | K12: =K11+J12 | L12: =L11*(1+Assumptions!$B$7) | M12: =K12-L12
A13: 8 | B13: =CHOOSE(MOD(A13-1,7)+1,"Mon","Tue","Wed","Thu","Fri","Sat","Sun") | C13: Hay cut 1 — East | D13: =Assumptions!$G$17*Assumptions!$H$17 | E13: 0 | F13: 0 | G13: 0 | H13: =(Assumptions!$B$9*Assumptions!$B$10*Assumptions!$B$11)-(Assumptions!$B$9*Assumptions!$B$12) | I13: =Assumptions!$E$17 | J13: =SUM(D13:H13)-I13 | K13: =K12+J13 | L13: =L12*(1+Assumptions!$B$7) | M13: =K13-L13
A14: 9 | B14: =CHOOSE(MOD(A14-1,7)+1,"Mon","Tue","Wed","Thu","Fri","Sat","Sun") | C14: Co-op repair job 2/3 | D14: 0 | E14: 0 | F14: 0 | G14: =Assumptions!$B$26 | H14: =(Assumptions!$B$9*Assumptions!$B$10*Assumptions!$B$11)-(Assumptions!$B$9*Assumptions!$B$12) | I14: =Assumptions!$B$27+Assumptions!$B$8 | J14: =SUM(D14:H14)-I14 | K14: =K13+J14 | L14: =L13*(1+Assumptions!$B$7) | M14: =K14-L14
A15: 10 | B15: =CHOOSE(MOD(A15-1,7)+1,"Mon","Tue","Wed","Thu","Fri","Sat","Sun") | C15: Buy salvage baler at Weaver's yard | D15: 0 | E15: 0 | F15: 0 | G15: 0 | H15: =(Assumptions!$B$9*Assumptions!$B$10*Assumptions!$B$11)-(Assumptions!$B$9*Assumptions!$B$12) | I15: =Assumptions!$B$29+Assumptions!$B$8 | J15: =SUM(D15:H15)-I15 | K15: =K14+J15 | L15: =L14*(1+Assumptions!$B$7) | M15: =K15-L15
A16: 11 | B16: =CHOOSE(MOD(A16-1,7)+1,"Mon","Tue","Wed","Thu","Fri","Sat","Sun") | C16: Co-op repair job 3/3 | D16: 0 | E16: 0 | F16: 0 | G16: =Assumptions!$B$26 | H16: =(Assumptions!$B$9*Assumptions!$B$10*Assumptions!$B$11)-(Assumptions!$B$9*Assumptions!$B$12) | I16: =Assumptions!$B$27+Assumptions!$B$8 | J16: =SUM(D16:H16)-I16 | K16: =K15+J16 | L16: =L15*(1+Assumptions!$B$7) | M16: =K16-L16
A17: 12 | B17: =CHOOSE(MOD(A17-1,7)+1,"Mon","Tue","Wed","Thu","Fri","Sat","Sun") | C17: Restoration parts for the flip | D17: 0 | E17: 0 | F17: 0 | G17: 0 | H17: =(Assumptions!$B$9*Assumptions!$B$10*Assumptions!$B$11)-(Assumptions!$B$9*Assumptions!$B$12) | I17: =Assumptions!$B$30 | J17: =SUM(D17:H17)-I17 | K17: =K16+J17 | L17: =L16*(1+Assumptions!$B$7) | M17: =K17-L17
A18: 13 | B18: =CHOOSE(MOD(A18-1,7)+1,"Mon","Tue","Wed","Thu","Fri","Sat","Sun") | D18: 0 | E18: 0 | F18: 0 | G18: 0 | H18: =(Assumptions!$B$9*Assumptions!$B$10*Assumptions!$B$11)-(Assumptions!$B$9*Assumptions!$B$12) | I18: 0 | J18: =SUM(D18:H18)-I18 | K18: =K17+J18 | L18: =L17*(1+Assumptions!$B$7) | M18: =K18-L18
A19: 14 | B19: =CHOOSE(MOD(A19-1,7)+1,"Mon","Tue","Wed","Thu","Fri","Sat","Sun") | D19: 0 | E19: 0 | F19: 0 | G19: 0 | H19: =(Assumptions!$B$9*Assumptions!$B$10*Assumptions!$B$11)-(Assumptions!$B$9*Assumptions!$B$12) | I19: 0 | J19: =SUM(D19:H19)-I19 | K19: =K18+J19 | L19: =L18*(1+Assumptions!$B$7) | M19: =K19-L19
A20: 15 | B20: =CHOOSE(MOD(A20-1,7)+1,"Mon","Tue","Wed","Thu","Fri","Sat","Sun") | C20: Hay cut 2 — East | D20: =Assumptions!$G$17*Assumptions!$H$17 | E20: 0 | F20: 0 | G20: 0 | H20: =(Assumptions!$B$9*Assumptions!$B$10*Assumptions!$B$11)-(Assumptions!$B$9*Assumptions!$B$12) | I20: =Assumptions!$E$17 | J20: =SUM(D20:H20)-I20 | K20: =K19+J20 | L20: =L19*(1+Assumptions!$B$7) | M20: =K20-L20
A21: 16 | B21: =CHOOSE(MOD(A21-1,7)+1,"Mon","Tue","Wed","Thu","Fri","Sat","Sun") | D21: 0 | E21: 0 | F21: 0 | G21: 0 | H21: =(Assumptions!$B$9*Assumptions!$B$10*Assumptions!$B$11)-(Assumptions!$B$9*Assumptions!$B$12) | I21: 0 | J21: =SUM(D21:H21)-I21 | K21: =K20+J21 | L21: =L20*(1+Assumptions!$B$7) | M21: =K21-L21
A22: 17 | B22: =CHOOSE(MOD(A22-1,7)+1,"Mon","Tue","Wed","Thu","Fri","Sat","Sun") | D22: 0 | E22: 0 | F22: 0 | G22: 0 | H22: =(Assumptions!$B$9*Assumptions!$B$10*Assumptions!$B$11)-(Assumptions!$B$9*Assumptions!$B$12) | I22: 0 | J22: =SUM(D22:H22)-I22 | K22: =K21+J22 | L22: =L21*(1+Assumptions!$B$7) | M22: =K22-L22
A23: 18 | B23: =CHOOSE(MOD(A23-1,7)+1,"Mon","Tue","Wed","Thu","Fri","Sat","Sun") | C23: Neighbor repair job 2 | D23: 0 | E23: 0 | F23: 0 | G23: =Assumptions!$B$28 | H23: =(Assumptions!$B$9*Assumptions!$B$10*Assumptions!$B$11)-(Assumptions!$B$9*Assumptions!$B$12) | I23: =Assumptions!$B$8 | J23: =SUM(D23:H23)-I23 | K23: =K22+J23 | L23: =L22*(1+Assumptions!$B$7) | M23: =K23-L23
A24: 19 | B24: =CHOOSE(MOD(A24-1,7)+1,"Mon","Tue","Wed","Thu","Fri","Sat","Sun") | D24: 0 | E24: 0 | F24: 0 | G24: 0 | H24: =(Assumptions!$B$9*Assumptions!$B$10*Assumptions!$B$11)-(Assumptions!$B$9*Assumptions!$B$12) | I24: 0 | J24: =SUM(D24:H24)-I24 | K24: =K23+J24 | L24: =L23*(1+Assumptions!$B$7) | M24: =K24-L24
A25: 20 | B25: =CHOOSE(MOD(A25-1,7)+1,"Mon","Tue","Wed","Thu","Fri","Sat","Sun") | D25: 0 | E25: 0 | F25: 0 | G25: 0 | H25: =(Assumptions!$B$9*Assumptions!$B$10*Assumptions!$B$11)-(Assumptions!$B$9*Assumptions!$B$12) | I25: 0 | J25: =SUM(D25:H25)-I25 | K25: =K24+J25 | L25: =L24*(1+Assumptions!$B$7) | M25: =K25-L25
A26: 21 | B26: =CHOOSE(MOD(A26-1,7)+1,"Mon","Tue","Wed","Thu","Fri","Sat","Sun") | D26: 0 | E26: 0 | F26: 0 | G26: 0 | H26: =(Assumptions!$B$9*Assumptions!$B$10*Assumptions!$B$11)-(Assumptions!$B$9*Assumptions!$B$12) | I26: 0 | J26: =SUM(D26:H26)-I26 | K26: =K25+J26 | L26: =L25*(1+Assumptions!$B$7) | M26: =K26-L26
A27: 22 | B27: =CHOOSE(MOD(A27-1,7)+1,"Mon","Tue","Wed","Thu","Fri","Sat","Sun") | C27: Hay cut 3 — East | D27: =Assumptions!$G$17*Assumptions!$H$17 | E27: 0 | F27: 0 | G27: 0 | H27: =(Assumptions!$B$9*Assumptions!$B$10*Assumptions!$B$11)-(Assumptions!$B$9*Assumptions!$B$12) | I27: =Assumptions!$E$17 | J27: =SUM(D27:H27)-I27 | K27: =K26+J27 | L27: =L26*(1+Assumptions!$B$7) | M27: =K27-L27
A28: 23 | B28: =CHOOSE(MOD(A28-1,7)+1,"Mon","Tue","Wed","Thu","Fri","Sat","Sun") | D28: 0 | E28: 0 | F28: 0 | G28: 0 | H28: =(Assumptions!$B$9*Assumptions!$B$10*Assumptions!$B$11)-(Assumptions!$B$9*Assumptions!$B$12) | I28: 0 | J28: =SUM(D28:H28)-I28 | K28: =K27+J28 | L28: =L27*(1+Assumptions!$B$7) | M28: =K28-L28
A29: 24 | B29: =CHOOSE(MOD(A29-1,7)+1,"Mon","Tue","Wed","Thu","Fri","Sat","Sun") | C29: Sell restored baler (flip complete) | D29: 0 | E29: 0 | F29: 0 | G29: =Assumptions!$B$31 | H29: =(Assumptions!$B$9*Assumptions!$B$10*Assumptions!$B$11)-(Assumptions!$B$9*Assumptions!$B$12) | I29: =Assumptions!$B$8 | J29: =SUM(D29:H29)-I29 | K29: =K28+J29 | L29: =L28*(1+Assumptions!$B$7) | M29: =K29-L29
A30: 25 | B30: =CHOOSE(MOD(A30-1,7)+1,"Mon","Tue","Wed","Thu","Fri","Sat","Sun") | D30: 0 | E30: 0 | F30: 0 | G30: 0 | H30: =(Assumptions!$B$9*Assumptions!$B$10*Assumptions!$B$11)-(Assumptions!$B$9*Assumptions!$B$12) | I30: 0 | J30: =SUM(D30:H30)-I30 | K30: =K29+J30 | L30: =L29*(1+Assumptions!$B$7) | M30: =K30-L30
A31: 26 | B31: =CHOOSE(MOD(A31-1,7)+1,"Mon","Tue","Wed","Thu","Fri","Sat","Sun") | D31: 0 | E31: 0 | F31: 0 | G31: 0 | H31: =(Assumptions!$B$9*Assumptions!$B$10*Assumptions!$B$11)-(Assumptions!$B$9*Assumptions!$B$12) | I31: 0 | J31: =SUM(D31:H31)-I31 | K31: =K30+J31 | L31: =L30*(1+Assumptions!$B$7) | M31: =K31-L31
A32: 27 | B32: =CHOOSE(MOD(A32-1,7)+1,"Mon","Tue","Wed","Thu","Fri","Sat","Sun") | D32: 0 | E32: 0 | F32: 0 | G32: 0 | H32: =(Assumptions!$B$9*Assumptions!$B$10*Assumptions!$B$11)-(Assumptions!$B$9*Assumptions!$B$12) | I32: 0 | J32: =SUM(D32:H32)-I32 | K32: =K31+J32 | L32: =L31*(1+Assumptions!$B$7) | M32: =K32-L32
A33: 28 | B33: =CHOOSE(MOD(A33-1,7)+1,"Mon","Tue","Wed","Thu","Fri","Sat","Sun") | D33: 0 | E33: 0 | F33: 0 | G33: 0 | H33: =(Assumptions!$B$9*Assumptions!$B$10*Assumptions!$B$11)-(Assumptions!$B$9*Assumptions!$B$12) | I33: 0 | J33: =SUM(D33:H33)-I33 | K33: =K32+J33 | L33: =L32*(1+Assumptions!$B$7) | M33: =K33-L33
A34: 29 | B34: =CHOOSE(MOD(A34-1,7)+1,"Mon","Tue","Wed","Thu","Fri","Sat","Sun") | D34: 0 | E34: 0 | F34: 0 | G34: 0 | H34: =(Assumptions!$B$9*Assumptions!$B$10*Assumptions!$B$11)-(Assumptions!$B$9*Assumptions!$B$12) | I34: 0 | J34: =SUM(D34:H34)-I34 | K34: =K33+J34 | L34: =L33*(1+Assumptions!$B$7) | M34: =K34-L34
A35: 30 | B35: =CHOOSE(MOD(A35-1,7)+1,"Mon","Tue","Wed","Thu","Fri","Sat","Sun") | D35: 0 | E35: 0 | F35: 0 | G35: 0 | H35: =(Assumptions!$B$9*Assumptions!$B$10*Assumptions!$B$11)-(Assumptions!$B$9*Assumptions!$B$12) | I35: 0 | J35: =SUM(D35:H35)-I35 | K35: =K34+J35 | L35: =L34*(1+Assumptions!$B$7) | M35: =K35-L35
A37: RUN SUMMARY
A38: Total spot sales | B38: =SUM(D6:D35)
A39: Total negotiated (rep) | B39: =SUM(E6:E35)
A40: Total timed (info) | B40: =SUM(F6:F35)
A41: Total repair & flip | B41: =SUM(G6:G35)
A42: Total eggs & favors | B42: =SUM(H6:H35)
...

Sheet Comparison
A1: THREE PATHS, SAME 30 DAYS
A2: Phase 0 exit criterion: every background solvent, every strategy distinct.
B4: Old School | C4: IT Nephew | D4: Mechanic
A5: End cash | B5: ='Old School'!B44 | C5: ='IT Nephew'!B44 | D5: ='Mechanic'!B44
A6: End debt | B6: ='Old School'!B45 | C6: ='IT Nephew'!B45 | D6: ='Mechanic'!B45
A7: Net worth delta | B7: ='Old School'!B46 | C7: ='IT Nephew'!B46 | D7: ='Mechanic'!B46
A8: Top income source | B8: ='Old School'!B47 | C8: ='IT Nephew'!B47 | D8: ='Mechanic'!B47
A9: Spot sales | B9: ='Old School'!B38 | C9: ='IT Nephew'!B38 | D9: ='Mechanic'!B38
A10: Negotiated (rep) | B10: ='Old School'!B39 | C10: ='IT Nephew'!B39 | D10: ='Mechanic'!B39
A11: Timed (info) | B11: ='Old School'!B40 | C11: ='IT Nephew'!B40 | D11: ='Mechanic'!B40
A12: Repair & flip | B12: ='Old School'!B41 | C12: ='IT Nephew'!B41 | D12: ='Mechanic'!B41
A13: Eggs & favors | B13: ='Old School'!B42 | C13: ='IT Nephew'!B42 | D13: ='Mechanic'!B42
A16: CHECKS
A17: All solvent (end cash > 0)? | B17: =IF(AND(B5>0,C5>0,D5>0),"PASS","FAIL")
A18: All improved net worth? | B18: =IF(AND(B7>0,C7>0,D7>0),"PASS","FAIL")
A19: Top income sources all different? | B19: =IF(AND(B8<>C8,B8<>D8,C8<>D8),"PASS","FAIL")
A20: Balance fairness (max/min end cash ≤ 1.25)? | B20: =IF(MAX(B5:D5)/MIN(B5:D5)<=1.25,"PASS","FAIL")
A23: Daily cash curves
A24: Day | B24: Old School | C24: IT Nephew | D24: Mechanic
A25: 1 | B25: ='Old School'!K6 | C25: ='IT Nephew'!K6 | D25: ='Mechanic'!K6
A26: 2 | B26: ='Old School'!K7 | C26: ='IT Nephew'!K7 | D26: ='Mechanic'!K7
A27: 3 | B27: ='Old School'!K8 | C27: ='IT Nephew'!K8 | D27: ='Mechanic'!K8
A28: 4 | B28: ='Old School'!K9 | C28: ='IT Nephew'!K9 | D28: ='Mechanic'!K9
A29: 5 | B29: ='Old School'!K10 | C29: ='IT Nephew'!K10 | D29: ='Mechanic'!K10
A30: 6 | B30: ='Old School'!K11 | C30: ='IT Nephew'!K11 | D30: ='Mechanic'!K11
A31: 7 | B31: ='Old School'!K12 | C31: ='IT Nephew'!K12 | D31: ='Mechanic'!K12
A32: 8 | B32: ='Old School'!K13 | C32: ='IT Nephew'!K13 | D32: ='Mechanic'!K13
A33: 9 | B33: ='Old School'!K14 | C33: ='IT Nephew'!K14 | D33: ='Mechanic'!K14
A34: 10 | B34: ='Old School'!K15 | C34: ='IT Nephew'!K15 | D34: ='Mechanic'!K15
A35: 11 | B35: ='Old School'!K16 | C35: ='IT Nephew'!K16 | D35: ='Mechanic'!K16
A36: 12 | B36: ='Old School'!K17 | C36: ='IT Nephew'!K17 | D36: ='Mechanic'!K17
... A54: 30 | B54: ='Old School'!K35 | C54: ='IT Nephew'!K35 | D54: ='Mechanic'!K35
